{"name": "test_delete_nonexistent_customer", "status": "broken", "statusDetails": {"message": "pymysql.err.OperationalError: (2013, 'Lost connection to MySQL server during query')", "trace": "request = <SubRequest 'connection' for <Function test_create_customer_and_verify_by_id>>\n\n    @pytest.fixture(scope=\"session\")\n    def connection(request):\n        host = request.config.getoption(\"--host\")\n        port = int(request.config.getoption(\"--port\"))\n        user = request.config.getoption(\"--user\")\n        password = request.config.getoption(\"--password\")\n        database = request.config.getoption(\"--database\")\n    \n>       conn = pymysql.connect(\n            host=host,\n            port=port,\n            user=user,\n            password=password,\n            database=database,\n            cursorclass=DictCursor,\n            autocommit=False  # для явного контроля транзакций\n        )\n\ntests/conftest.py:20: \n_ _ _ _ _ _ _ _ _ _ _ _ _ _ _ _ _ _ _ _ _ _ _ _ _ _ _ _ _ _ _ _ _ _ _ _ _ _ _ _ _ _ _ _ _ _ _ _ _ _ _ _ _ _ _ _ _ _ _ _ _ _ _ _ _ _ _ _ _ _ _ _ _ _ _ _ _ _ _ _ _ \n.venv/lib/python3.13/site-packages/pymysql/connections.py:361: in __init__\n    self.connect()\n.venv/lib/python3.13/site-packages/pymysql/connections.py:668: in connect\n    self._get_server_information()\n.venv/lib/python3.13/site-packages/pymysql/connections.py:1098: in _get_server_information\n    packet = self._read_packet()\n.venv/lib/python3.13/site-packages/pymysql/connections.py:744: in _read_packet\n    packet_header = self._read_bytes(4)\n_ _ _ _ _ _ _ _ _ _ _ _ _ _ _ _ _ _ _ _ _ _ _ _ _ _ _ _ _ _ _ _ _ _ _ _ _ _ _ _ _ _ _ _ _ _ _ _ _ _ _ _ _ _ _ _ _ _ _ _ _ _ _ _ _ _ _ _ _ _ _ _ _ _ _ _ _ _ _ _ _ \n\nself = <pymysql.connections.Connection object at 0x105ba9d30>, num_bytes = 4\n\n    def _read_bytes(self, num_bytes):\n        self._sock.settimeout(self._read_timeout)\n        while True:\n            try:\n                data = self._rfile.read(num_bytes)\n                break\n            except OSError as e:\n                if e.errno == errno.EINTR:\n                    continue\n                self._force_close()\n                raise err.OperationalError(\n                    CR.CR_SERVER_LOST,\n                    f\"Lost connection to MySQL server during query ({e})\",\n                )\n            except BaseException:\n                # Don't convert unknown exception to MySQLError.\n                self._force_close()\n                raise\n        if len(data) < num_bytes:\n            self._force_close()\n>           raise err.OperationalError(\n                CR.CR_SERVER_LOST, \"Lost connection to MySQL server during query\"\n            )\nE           pymysql.err.OperationalError: (2013, 'Lost connection to MySQL server during query')\n\n.venv/lib/python3.13/site-packages/pymysql/connections.py:798: OperationalError"}, "start": 1746280099807, "stop": 1746280099807, "uuid": "349f367e-02f5-466f-8df4-1ccac9c5a17d", "historyId": "aa00ae1a43c01686966b11db7e86ae8f", "testCaseId": "aa00ae1a43c01686966b11db7e86ae8f", "fullName": "tests.test_customer#test_delete_nonexistent_customer", "labels": [{"name": "severity", "value": "minor"}, {"name": "feature", "value": "Клиенты"}, {"name": "story", "value": "Негативное удаление несуществующего клиента"}, {"name": "parentSuite", "value": "tests"}, {"name": "suite", "value": "test_customer"}, {"name": "host", "value": "MacBook-Air-2.local"}, {"name": "thread", "value": "8470-MainThread"}, {"name": "framework", "value": "pytest"}, {"name": "language", "value": "cpython3"}, {"name": "package", "value": "tests.test_customer"}]}